<?xml version="1.0" encoding="utf-8"?>
<!-- This URDF was automatically created by SolidWorks to URDF Exporter! Originally created by Stephen Brawner (brawner@gmail.com) 
     Commit Version: 1.6.0-4-g7f85cfe  Build Version: 1.6.7995.38578
     For more information, please see http://wiki.ros.org/sw_urdf_exporter -->
<robot
  name="delivery_robot">
  <link
    name="base_link">
    <inertial>
      <origin
        xyz="-1.27106972964244E-06 -9.59828024615475E-07 0.0811861255278657"
        rpy="0 0 0" />
      <mass
        value="3.92914679746778" />
      <inertia
        ixx="0.0709913559982132"
        ixy="-4.66341141992368E-09"
        ixz="1.28848003734999E-07"
        iyy="0.0698537239159662"
        iyz="6.33255474854818E-08"
        izz="0.138972444682359" />
    </inertial>
    <visual>
      <origin
        xyz="0 0 0"
        rpy="0 0 0" />
      <geometry>
        <mesh
          filename="package://delivery_robot/meshes/base_link.STL" />
      </geometry>
      <material
        name="">
        <color
          rgba="0.792156862745098 0.819607843137255 0.933333333333333 1" />
      </material>
    </visual>
    <collision>
      <origin
        xyz="0 0 0"
        rpy="0 0 0" />
      <geometry>
        <mesh
          filename="package://delivery_robot/meshes/base_link.STL" />
      </geometry>
    </collision>
  </link>
  <link
    name="right_wheel">
    <inertial>
      <origin
        xyz="2.40836024367927E-16 -4.16333634234434E-17 -0.0178996642599887"
        rpy="0 0 0" />
      <mass
        value="0.158485151112061" />
      <inertia
        ixx="0.000224621670813498"
        ixy="1.8128826346836E-19"
        ixz="3.69302677105076E-19"
        iyy="0.000224621670813498"
        iyz="6.9524792075622E-21"
        izz="0.000438658164269869" />
    </inertial>
    <visual>
      <origin
        xyz="0 0 0"
        rpy="0 0 0" />
      <geometry>
        <mesh
          filename="package://delivery_robot/meshes/right_wheel.STL" />
      </geometry>
      <material
        name="">
        <color
          rgba="0.792156862745098 0.819607843137255 0.933333333333333 1" />
      </material>
    </visual>
    <collision>
      <origin
        xyz="0 0 0"
        rpy="0 0 0" />
      <geometry>
        <mesh
          filename="package://delivery_robot/meshes/right_wheel.STL" />
      </geometry>
    </collision>
  </link>
  <joint
    name="right_wheel_joint"
    type="continuous">
    <origin
      xyz="0 -0.239998 0.03925"
      rpy="1.5707963267949 0 0" />
    <parent
      link="base_link" />
    <child
      link="right_wheel" />
    <axis
      xyz="0 0 1" />
  </joint>
  <link
    name="left_wheel">
    <inertial>
      <origin
        xyz="-5.34498900112382E-17 -5.55111512312578E-17 -0.0178996642599887"
        rpy="0 0 0" />
      <mass
        value="0.158485151112061" />
      <inertia
        ixx="0.000224621670813498"
        ixy="-1.83517773713129E-19"
        ixz="7.43982371881285E-19"
        iyy="0.000224621670813499"
        iyz="8.18535951933032E-19"
        izz="0.00043865816426987" />
    </inertial>
    <visual>
      <origin
        xyz="0 0 0"
        rpy="0 0 0" />
      <geometry>
        <mesh
          filename="package://delivery_robot/meshes/left_wheel.STL" />
      </geometry>
      <material
        name="">
        <color
          rgba="0.792156862745098 0.819607843137255 0.933333333333333 1" />
      </material>
    </visual>
    <collision>
      <origin
        xyz="0 0 0"
        rpy="0 0 0" />
      <geometry>
        <mesh
          filename="package://delivery_robot/meshes/left_wheel.STL" />
      </geometry>
    </collision>
  </link>
  <joint
    name="left_wheel_joint"
    type="continuous">
    <origin
      xyz="0 0.239998 0.0392500000000001"
      rpy="1.5707963267949 0 3.14159265358979" />
    <parent
      link="base_link" />
    <child
      link="left_wheel" />
    <axis
      xyz="0 0 -1" />
  </joint>

    <gazebo>
    <plugin name="gazebo_ros_control" filename="libgazebo_ros_control.so">
    </plugin>
  </gazebo>



  <transmission name="tran1">
    <type>transmission_interface/SimpleTransmission</type>
    <joint name="right_wheel_joint">
      <hardwareInterface>hardware_interface/VelocityJointInterface</hardwareInterface>
    </joint>
    <actuator name="motor1">
      <hardwareInterface>hardware_interface/VelocityJointInterface</hardwareInterface>
      <mechanicalReduction>1</mechanicalReduction>
    </actuator>
  </transmission>

  <transmission name="tran2">
    <type>transmission_interface/SimpleTransmission</type>
    <joint name="left_wheel_joint">
      <hardwareInterface>hardware_interface/VelocityJointInterface</hardwareInterface>
    </joint>
    <actuator name="motor2">
      <hardwareInterface>hardware_interface/VelocityJointInterface</hardwareInterface>
      <mechanicalReduction>1</mechanicalReduction>
    </actuator>
  </transmission>

  <link name="camera_link">
    <origin xyz="0 0 0" rpy="0 0 0"/>
    <visual>
        <origin xyz="0 0 0" rpy="0 0 0"/>
        <geometry>
            <mesh filename="package://delivery_robot/kinect/meshes/kinect.dae" />
        </geometry>
    </visual>
    <collision>
        <geometry>
            <box size="0.07 0.3 0.09"/>
        </geometry>
    </collision>
</link>

<joint name="camera_optical_joint" type="fixed">
    <origin xyz="0 0 0" rpy="-1.5708 0 -1.5708"/>
    <parent link="camera_link"/>
    <child link="camera_frame_optical"/>
</joint>
<link name="camera_frame_optical"/>

<joint name="camera_frame_joint" type="fixed">
<origin xyz="0.3 0 0.06"
        rpy="0 0 0" />
<parent link="base_link"/>
<child link="camera_link"/>
</joint>


<gazebo reference="camera_link">
<sensor type="depth" name="camera">
<always_on>true</always_on>
<update_rate>20.0</update_rate>
<camera>
    <horizontal_fov>1</horizontal_fov>
    <image>
        <format>R8G8B8</format>
        <width>640</width>
        <height>480</height>
    </image>
    <clip>
        <near>0.05</near>
        <far>8.0</far>
    </clip>
</camera>
<plugin name="kinect_camera_controller" filename="libgazebo_ros_openni_kinect.so">
    <cameraName>camera</cameraName>
    <alwaysOn>true</alwaysOn>
    <updateRate>10</updateRate>
    <imageTopicName>/rgb/image_raw</imageTopicName>
    <depthImageTopicName>/depth/image_raw</depthImageTopicName>
    <pointCloudTopicName>/depth/points</pointCloudTopicName>
    <cameraInfoTopicName>/rgb/camera_info</cameraInfoTopicName>
    <depthImageCameraInfoTopicName>/depth/camera_info</depthImageCameraInfoTopicName>
    <frameName>camera_frame_optical</frameName>
    <baseline>0.1</baseline>
    <distortion_k1>0.0</distortion_k1>
    <distortion_k2>0.0</distortion_k2>
    <distortion_k3>0.0</distortion_k3>
    <distortion_t1>0.0</distortion_t1>
    <distortion_t2>0.0</distortion_t2>
    <pointCloudCutoff>0.4</pointCloudCutoff>
</plugin>
</sensor>
</gazebo>

</robot>
