<?xml version="1.0" encoding="utf-8"?>
<!-- This URDF was automatically created by SolidWorks to URDF Exporter! Originally created by Stephen Brawner (brawner@gmail.com) 
     Commit Version: 1.6.0-4-g7f85cfe  Build Version: 1.6.7995.38578
     For more information, please see http://wiki.ros.org/sw_urdf_exporter -->
<robot name="delivery_robot">

  <link name="base_link">
    <inertial>
      <origin xyz="9.1429E-05 3.4592E-05 0.10853" rpy="0 0 0" />
      <mass value="5.1663" />
      <inertia ixx="0.071613" ixy="3.168E-07" ixz="-7.3138E-08" iyy="0.071749" iyz="1.4679E-08" izz="0.1407" />
    </inertial>
    <visual>
      <origin xyz="0 0 0" rpy="0 0 0" />
      <geometry>
        <mesh filename="package://delivery_robot/meshes/base_link.STL" />
      </geometry>
      <material name="">
        <color rgba="0.79216 0.81961 0.93333 1" />
      </material>
    </visual>
    <collision>
      <origin xyz="0 0 0" rpy="0 0 0" />
      <geometry>
        <mesh filename="package://delivery_robot/meshes/base_link.STL" />
      </geometry>
    </collision>
  </link>
  <link name="right_wheel">
    <inertial>
      <origin xyz="-1.9375E-16 -1.3878E-17 -0.0176" rpy="0 0 0" />
      <mass value="0.15849" />
      <inertia ixx="0.00022462" ixy="7.4698E-20" ixz="6.3967E-20" iyy="0.00022462" iyz="-1.3556E-20" izz="0.00043866" />
    </inertial>
    <visual>
      <origin xyz="0 0 0" rpy="0 0 0" />
      <geometry>
        <mesh filename="package://delivery_robot/meshes/right_wheel.STL" />
      </geometry>
      <material name="">
        <color rgba="0.79216 0.81961 0.93333 1" />
      </material>
    </visual>
    <collision>
      <origin xyz="0 0 0" rpy="0 0 0" />
      <geometry>
        <mesh filename="package://delivery_robot/meshes/right_wheel.STL" />
      </geometry>
    </collision>
  </link>
  <joint name="right_wheel_joint" type="continuous">
    <origin xyz="-0.2435 0 0.06725" rpy="1.5708 0 -1.5708" />
    <parent link="base_link" />
    <child link="right_wheel" />
    <axis xyz="0 0 1" />
  </joint>
  <link name="left_wheel">
    <inertial>
      <origin xyz="-5.36E-06 -0.00030712 -0.017598" rpy="0 0 0" />
      <mass value="0.15849" />
      <inertia ixx="0.00022462" ixy="1.1374E-09" ixz="6.5173E-08" iyy="0.00022469" iyz="3.7343E-06" izz="0.00043859" />
    </inertial>
    <visual>
      <origin xyz="0 0 0" rpy="0 0 0" />
      <geometry>
        <mesh filename="package://delivery_robot/meshes/left_wheel.STL" />
      </geometry>
      <material name="">
        <color rgba="0.79216 0.81961 0.93333 1" />
      </material>
    </visual>
    <collision>
      <origin xyz="0 0 0" rpy="0 0 0" />
      <geometry>
        <mesh filename="package://delivery_robot/meshes/left_wheel.STL" />
      </geometry>
    </collision>
  </link>
  <joint name="left_wheel_joint" type="continuous">
    <origin xyz="0.2435 0 0.06725" rpy="-1.5533 0.017448 -1.5705" />
    <parent link="base_link" />
    <child link="left_wheel" />
    <axis xyz="0 0 -1" />
  </joint>

<link name="laser">
    <visual>
      <origin xyz="0 0 0.0" rpy="0 0 0"/>
      <geometry>
        <mesh filename="package://delivery_robot/meshes/lds.stl" scale="0.001 0.001 0.001"/>
      </geometry>
    </visual>

    <collision>
      <origin xyz="0.015 0 -0.0065" rpy="0 0 0"/>
      <geometry>
        <cylinder length="0.0315" radius="0.055"/>
      </geometry>
    </collision>

    <inertial>
      <mass value="0.114" />
      <origin xyz="0 0 0" />
      <inertia ixx="0.001" ixy="0.0" ixz="0.0"
               iyy="0.001" iyz="0.0"
               izz="0.001" />
    </inertial>
  </link>
  <joint name="laser_joint" type="fixed">
    <axis xyz="0 1 0" />
    <origin xyz="0.0 0 0.244" rpy="0 0 0" />
    <parent link="base_link" />
    <child link="laser" />
  </joint>

<gazebo reference="laser">
    <material>Gazebo/FlatBlack</material>
    <sensor type="ray" name="lds_lfcd_sensor">
      <pose>0 0 0 0 0 0</pose>
      <visualize>true</visualize>
      <update_rate>5</update_rate>
      <ray>
        <scan>
          <horizontal>
            <samples>360</samples>
            <resolution>1</resolution>
            <min_angle>0.0</min_angle>
            <max_angle>6.28319</max_angle>
          </horizontal>
        </scan>
        <range>
          <min>0.120</min>
          <max>3.5</max>
          <resolution>0.015</resolution>
        </range>
        <noise>
          <type>gaussian</type>
          <mean>0.0</mean>
          <stddev>0.01</stddev>
        </noise>
      </ray>
      <plugin name="gazebo_ros_lds_lfcd_controller" filename="libgazebo_ros_laser.so">
        <topicName>base_scan</topicName>
        <frameName>laser</frameName>
      </plugin>
    </sensor>
  </gazebo>
      ------ step one: add gazebo plugin -----
      ------ should it be added above? -----
  <!-- <gazebo>
    <plugin name="gazebo_ros_control" filename="libgazebo_ros_control.so">
    </plugin>
  </gazebo>

  <transmission name="tran1">
    <type>transmission_interface/SimpleTransmission</type>
    <joint name="right_wheel_joint">
      <hardwareInterface>hardware_interface/VelocityJointInterface</hardwareInterface>
    </joint>
    <actuator name="motor1">
      <hardwareInterface>hardware_interface/VelocityJointInterface</hardwareInterface>
      <mechanicalReduction>1</mechanicalReduction>
    </actuator>
  </transmission>

  <transmission name="tran2">
    <type>transmission_interface/SimpleTransmission</type>
    <joint name="left_wheel_joint">
      <hardwareInterface>hardware_interface/VelocityJointInterface</hardwareInterface>
    </joint>
    <actuator name="motor2">
      <hardwareInterface>hardware_interface/VelocityJointInterface</hardwareInterface>
      <mechanicalReduction>1</mechanicalReduction>
    </actuator>
  </transmission> -->
  <!-- <gazebo>
    <plugin name="delivery_robot_controller" filename="libgazebo_ros_diff_drive.so">
      <commandTopic>cmd_vel</commandTopic>
      <odometryTopic>odom</odometryTopic>
      <odometryFrame>odom</odometryFrame>
      <odometrySource>world</odometrySource>
      <publishOdomTF>true</publishOdomTF>
      <robotBaseFrame>base_footprint</robotBaseFrame>
      <publishWheelTF>false</publishWheelTF>
      <publishTf>true</publishTf>
      <publishWheelJointState>true</publishWheelJointState>
      <legacyMode>false</legacyMode>
      <updateRate>30</updateRate>
      <leftJoint>left_wheel_joint</leftJoint>
      <rightJoint>right_wheel_joint</rightJoint>
      <wheelSeparation>0.455</wheelSeparation>
      <wheelDiameter>0.13</wheelDiameter>
      <wheelAcceleration>1</wheelAcceleration>
      <wheelTorque>10</wheelTorque>
      <rosDebugLevel>na</rosDebugLevel>
    </plugin>
  </gazebo> -->
</robot>
