<?xml version="1.0" encoding="utf-8"?>
<!-- This URDF was automatically created by SolidWorks to URDF Exporter! Originally created by Stephen Brawner (brawner@gmail.com) 
     Commit Version: 1.6.0-4-g7f85cfe  Build Version: 1.6.7995.38578
     For more information, please see http://wiki.ros.org/sw_urdf_exporter -->
<robot
  name="delivery_robot">
  <link
    name="base_link">
    <inertial>
      <origin
        xyz="-1.27106972964244E-06 -9.59828024615475E-07 0.0811861255278657"
        rpy="0 0 0" />
      <mass
        value="3.92914679746778" />
      <inertia
        ixx="0.0709913559982132"
        ixy="-4.66341141992368E-09"
        ixz="1.28848003734999E-07"
        iyy="0.0698537239159662"
        iyz="6.33255474854818E-08"
        izz="0.138972444682359" />
    </inertial>
    <visual>
      <origin
        xyz="0 0 0"
        rpy="0 0 0" />
      <geometry>
        <mesh
          filename="package://delivery_robot/meshes/base_link.STL" />
      </geometry>
      <material
        name="">
        <color
          rgba="0.792156862745098 0.819607843137255 0.933333333333333 1" />
      </material>
    </visual>
    <collision>
      <origin
        xyz="0 0 0"
        rpy="0 0 0" />
      <geometry>
        <mesh
          filename="package://delivery_robot/meshes/base_link.STL" />
      </geometry>
    </collision>
  </link>
  <link
    name="right_wheel">
    <inertial>
      <origin
        xyz="2.40836024367927E-16 -4.16333634234434E-17 -0.0178996642599887"
        rpy="0 0 0" />
      <mass
        value="0.158485151112061" />
      <inertia
        ixx="0.000224621670813498"
        ixy="1.8128826346836E-19"
        ixz="3.69302677105076E-19"
        iyy="0.000224621670813498"
        iyz="6.9524792075622E-21"
        izz="0.000438658164269869" />
    </inertial>
    <visual>
      <origin
        xyz="0 0 0"
        rpy="0 0 0" />
      <geometry>
        <mesh
          filename="package://delivery_robot/meshes/right_wheel.STL" />
      </geometry>
      <material
        name="">
        <color
          rgba="0.792156862745098 0.819607843137255 0.933333333333333 1" />
      </material>
    </visual>
    <collision>
      <origin
        xyz="0 0 0"
        rpy="0 0 0" />
      <geometry>
        <mesh
          filename="package://delivery_robot/meshes/right_wheel.STL" />
      </geometry>
    </collision>
  </link>
  <joint
    name="right_wheel_joint"
    type="continuous">
    <origin
      xyz="0 -0.239998 0.03925"
      rpy="1.5707963267949 0 0" />
    <parent
      link="base_link" />
    <child
      link="right_wheel" />
    <axis
      xyz="0 0 1" />
  </joint>
  <link
    name="left_wheel">
    <inertial>
      <origin
        xyz="-5.34498900112382E-17 -5.55111512312578E-17 -0.0178996642599887"
        rpy="0 0 0" />
      <mass
        value="0.158485151112061" />
      <inertia
        ixx="0.000224621670813498"
        ixy="-1.83517773713129E-19"
        ixz="7.43982371881285E-19"
        iyy="0.000224621670813499"
        iyz="8.18535951933032E-19"
        izz="0.00043865816426987" />
    </inertial>
    <visual>
      <origin
        xyz="0 0 0"
        rpy="0 0 0" />
      <geometry>
        <mesh
          filename="package://delivery_robot/meshes/left_wheel.STL" />
      </geometry>
      <material
        name="">
        <color
          rgba="0.792156862745098 0.819607843137255 0.933333333333333 1" />
      </material>
    </visual>
    <collision>
      <origin
        xyz="0 0 0"
        rpy="0 0 0" />
      <geometry>
        <mesh
          filename="package://delivery_robot/meshes/left_wheel.STL" />
      </geometry>
    </collision>
  </link>
  <joint
    name="left_wheel_joint"
    type="continuous">
    <origin
      xyz="0 0.239998 0.0392500000000001"
      rpy="1.5707963267949 0 3.14159265358979" />
    <parent
      link="base_link" />
    <child
      link="left_wheel" />
    <axis
      xyz="0 0 -1" />
  </joint>

    <gazebo>
    <plugin name="gazebo_ros_control" filename="libgazebo_ros_control.so">
    </plugin>
  </gazebo>
  <link name="laser">
    <visual>
      <origin xyz="0 0 0.0" rpy="0 0 0"/>
      <geometry>
        <mesh filename="package://delivery_robot/meshes/lds.stl" scale="0.001 0.001 0.001"/>
      </geometry>
    </visual>

    <collision>
      <origin xyz="0.015 0 -0.0065" rpy="0 0 0"/>
      <geometry>
        <cylinder length="0.0315" radius="0.055"/>
      </geometry>
    </collision>

    <inertial>
      <mass value="0.114" />
      <origin xyz="0 0 0" />
      <inertia ixx="0.001" ixy="0.0" ixz="0.0"
               iyy="0.001" iyz="0.0"
               izz="0.001" />
    </inertial>
  </link>
  <joint name="laser_joint" type="fixed">
    <axis xyz="0 1 0" />
    <origin xyz="0.0 0 0.244" rpy="0 0 0" />
    <parent link="base_link" />
    <child link="laser" />
  </joint>

  <gazebo reference="laser">
    <material>Gazebo/FlatBlack</material>
    <sensor type="ray" name="lds_lfcd_sensor">
      <pose>0 0 0 0 0 0</pose>
      <visualize>true</visualize>
      <update_rate>5</update_rate>
      <ray>
        <scan>
          <horizontal>
            <samples>360</samples>
            <resolution>1</resolution>
            <min_angle>0.0</min_angle>
            <max_angle>6.28319</max_angle>
          </horizontal>
        </scan>
        <range>
          <min>0.120</min>
          <max>3.5</max>
          <resolution>0.015</resolution>
        </range>
        <noise>
          <type>gaussian</type>
          <mean>0.0</mean>
          <stddev>0.01</stddev>
        </noise>
      </ray>
      <plugin name="gazebo_ros_lds_lfcd_controller" filename="libgazebo_ros_laser.so">
        <topicName>base_scan</topicName>
        <frameName>laser</frameName>
      </plugin>
    </sensor>
  </gazebo>
  
  <transmission name="tran1">
    <type>transmission_interface/SimpleTransmission</type>
    <joint name="right_wheel_joint">
      <hardwareInterface>hardware_interface/VelocityJointInterface</hardwareInterface>
    </joint>
    <actuator name="motor1">
      <hardwareInterface>hardware_interface/VelocityJointInterface</hardwareInterface>
      <mechanicalReduction>1</mechanicalReduction>
    </actuator>
  </transmission>

  <transmission name="tran2">
    <type>transmission_interface/SimpleTransmission</type>
    <joint name="left_wheel_joint">
      <hardwareInterface>hardware_interface/VelocityJointInterface</hardwareInterface>
    </joint>
    <actuator name="motor2">
      <hardwareInterface>hardware_interface/VelocityJointInterface</hardwareInterface>
      <mechanicalReduction>1</mechanicalReduction>
    </actuator>
  </transmission>

</robot>
